Workbook

Sheet Panduan
A1: SINGGAH COFFEE — PANDUAN EDIT, TAMBAH & HAPUS MENU
A2: Baca ini dulu sebelum mengubah struktur menu. Kalau ragu, lebih aman minta bantuan AI/Claude untuk eksekusi ketimbang edit manual.
A4: ✏️ A. EDIT MENU (ganti nama, resep, atau harga) — PALING MUDAH, LANGSUNG BISA
A6: 1. Ganti NAMA menu → edit HANYA di sheet "HPP & Harga Jual", kolom B (baris 5-14). Otomatis merambat ke semua sheet lain.
A7: 2. Ganti/tambah/kurangi BAHAN dalam satu resep → sheet "Resep Menu", kolom D (Nama Bahan): klik sel, pilih dari dropdown ▼. Kolom Kode Bahan (C) otomatis ikut.
A8: 3. Ganti TAKARAN bahan (gram/ml) → sheet "Resep Menu", kolom E (Qty/Cup) — ketik angka baru langsung.
A9: 4. Ganti HARGA BELI bahan → sheet "Master Bahan Baku", kolom D (Harga Beli). Otomatis merambat ke semua HPP.
A10: 5. Ganti target margin/food cost → sheet "HPP & Harga Jual", kolom F (Target Food Cost %) per menu.
A12: ➕ B. TAMBAH MENU BARU — ikuti urutan ini PERSIS
A14: Langkah 1 — sheet "HPP & Harga Jual": sisipkan 1 baris baru sebelum baris RATA-RATA (baris 15 saat ini). Isi kolom A (nomor urut), B (nama menu), D (biaya operasional, contoh: 4000), F (target food cost, contoh: 0.8). Kolom C,E,G,H,I,J: COPY formula dari baris menu di atasnya (klik baris atasnya, Ctrl+C, lalu paste ke baris baru — jangan ketik ulang).
A15: Langkah 2 — sheet "Resep Menu": di baris PALING BAWAH data (setelah baris terakhir), tambahkan baris untuk tiap bahan resep menu baru. Kolom A: isi nomor urut menu (angka berikutnya). Kolom B,C,G,H: COPY formula dari baris menu lain (jangan ketik ulang — cukup copy-paste satu baris lalu isi D,E,F-nya). Kolom D: pilih bahan dari dropdown. Kolom I: copy formula forward-fill dari baris di atasnya.
A16: Langkah 3 — sheet "Kebutuhan Stok", Bagian A (baris 6-15): sisipkan 1 baris baru di akhir Bagian A (sebelum baris "Catatan"). Kolom A,B: COPY formula dari baris di atasnya lalu ganti nomor sumber (mis. 'HPP & Harga Jual'!A15). Kolom G: isi target cup (sel biru).
... A29: Yang MASIH perlu langkah manual (Bagian B di atas): menambah BARIS BARU itu sendiri (baris menu baru di HPP&HargaJual, baris resep baru di Resep Menu, baris target cup baru di Kebutuhan Stok) — karena ini soal STRUKTUR baris, bukan soal rentang rumus.

Sheet Ringkasan
A1: SINGGAH COFFEE — RINGKASAN BISNIS
A2: Dashboard ringkas: HPP, harga jual, margin tiap menu, dan status Break Even Point.
A4: A. RINGKASAN HPP & HARGA JUAL PER MENU
A5: No | B5: Nama Menu | C5: Total HPP (Rp) | D5: Harga Jual (Rp) | E5: Margin/Cup (Rp) | F5: Margin %
A6: ='HPP & Harga Jual'!A5 -> 1 | B6: ='HPP & Harga Jual'!B5 -> Kopsu Gula Aren | C6: ='HPP & Harga Jual'!E5 -> 11765 | D6: ='HPP & Harga Jual'!H5 -> 14500 | E6: ='HPP & Harga Jual'!I5 -> 2735 | F6: ='HPP & Harga Jual'!J5 -> 0.18862069
A7: ='HPP & Harga Jual'!A6 -> 2 | B7: ='HPP & Harga Jual'!B6 -> Kopsu Original | C7: ='HPP & Harga Jual'!E6 -> 11215 | D7: ='HPP & Harga Jual'!H6 -> 14000 | E7: ='HPP & Harga Jual'!I6 -> 2785 | F7: ='HPP & Harga Jual'!J6 -> 0.19892857
A8: ='HPP & Harga Jual'!A7 -> 3 | B8: ='HPP & Harga Jual'!B7 -> Americano (Es) | C8: ='HPP & Harga Jual'!E7 -> 7290 | D8: ='HPP & Harga Jual'!H7 -> 9000 | E8: ='HPP & Harga Jual'!I7 -> 1710 | F8: ='HPP & Harga Jual'!J7 -> 0.19
A9: ='HPP & Harga Jual'!A8 -> 4 | B9: ='HPP & Harga Jual'!B8 -> Cappuccino (Panas) | C9: ='HPP & Harga Jual'!E8 -> 12025 | D9: ='HPP & Harga Jual'!H8 -> 15000 | E9: ='HPP & Harga Jual'!I8 -> 2975 | F9: ='HPP & Harga Jual'!J8 -> 0.19833333
A10: ='HPP & Harga Jual'!A9 -> 5 | B10: ='HPP & Harga Jual'!B9 -> Matcha | C10: ='HPP & Harga Jual'!E9 -> 17660 | D10: ='HPP & Harga Jual'!H9 -> 22000 | E10: ='HPP & Harga Jual'!I9 -> 4340 | F10: ='HPP & Harga Jual'!J9 -> 0.19727273
A11: ='HPP & Harga Jual'!A10 -> 6 | B11: ='HPP & Harga Jual'!B10 -> Kopsu Singgah Aren | C11: ='HPP & Harga Jual'!E10 -> 13495 | D11: ='HPP & Harga Jual'!H10 -> 17000 | E11: ='HPP & Harga Jual'!I10 -> 3505 | F11: ='HPP & Harga Jual'!J10 -> 0.20617647
A12: ='HPP & Harga Jual'!A11 -> 7 | B12: ='HPP & Harga Jual'!B11 -> Butterscotch Latte | C12: ='HPP & Harga Jual'!E11 -> 13625 | D12: ='HPP & Harga Jual'!H11 -> 17000 | E12: ='HPP & Harga Jual'!I11 -> 3375 | F12: ='HPP & Harga Jual'!J11 -> 0.19852941
A13: ='HPP & Harga Jual'!A12 -> 8 | B13: ='HPP & Harga Jual'!B12 -> Kopsu Singgah | C13: ='HPP & Harga Jual'!E12 -> 12825 | D13: ='HPP & Harga Jual'!H12 -> 16000 | E13: ='HPP & Harga Jual'!I12 -> 3175 | F13: ='HPP & Harga Jual'!J12 -> 0.1984375
A14: ='HPP & Harga Jual'!A13 -> 9 | B14: ='HPP & Harga Jual'!B13 -> Oatside Signature | C14: ='HPP & Harga Jual'!E13 -> 12450 | D14: ='HPP & Harga Jual'!H13 -> 15500 | E14: ='HPP & Harga Jual'!I13 -> 3050 | F14: ='HPP & Harga Jual'!J13 -> 0.19677419
A15: ='HPP & Harga Jual'!A14 -> 10 | B15: ='HPP & Harga Jual'!B14 -> Oatside Signature Gula Aren | C15: ='HPP & Harga Jual'!E14 -> 13100 | D15: ='HPP & Harga Jual'!H14 -> 16500 | E15: ='HPP & Harga Jual'!I14 -> 3400 | F15: ='HPP & Harga Jual'!J14 -> 0.20606061
B17: Menu dengan Margin Rp Tertinggi | C17: =INDEX(B6:B15,MATCH(MAX(E6:E15),E6:E15,0)) -> Matcha
A19: B. RINGKASAN BEP (BREAK EVEN POINT)
A20: Total Biaya Tetap / Bulan | D20: =BEP!C13 -> 3900000
A21: Rata-rata Margin Kontribusi / Cup | D21: =BEP!C18 -> 3105
A22: BEP (Cup) per Bulan | D22: =BEP!C21 -> 1257
A23: BEP (Rupiah) per Bulan | D23: =BEP!C22 -> 19657005
A24: BEP (Cup) per Hari | D24: =BEP!C23 -> 42
A25: Estimasi Penjualan per Bulan (asumsi) | D25: =BEP!C27 -> 1500
A26: Proyeksi Laba Bersih / Bulan | D26: =BEP!C28 -> 757500
A27: Estimasi Balik Modal | D27: =BEP!C33 -> 52.9

Sheet Master Bahan Baku
A1: SINGGAH COFFEE — MASTER HARGA BAHAN BAKU
A2: Sumber acuan harga: Otten Coffee, Majoo, Ginee, KoinWorks (riset pasar Jul 2026). Sel biru = boleh diedit sesuai harga supplier Anda.
A4: Kode | B4: Nama Bahan | C4: Kategori | D4: Harga Beli (Rp) | E4: Satuan Beli | F4: Isi per Satuan Beli | G4: Satuan Kecil | H4: Harga per Satuan Kecil (Rp)
A5: B01 | B5: Kopi Robusta Bubuk/Biji | C5: Kopi | D5: 126000 | E5: kg | F5: 1000 | G5: gram | H5: =D5/F5 -> 126
A6: B02 | B6: Kopi Blend Bubuk/Biji | C6: Kopi | D6: 200000 | E6: kg | F6: 1000 | G6: gram | H6: =D6/F6 -> 200
A7: B03 | B7: Susu Full Cream UHT | C7: Susu | D7: 22000 | E7: liter | F7: 1000 | G7: ml | H7: =D7/F7 -> 22
A8: B05 | B8: Gula Aren Cair (Palm Sugar Syrup) | C8: Pemanis | D8: 35000 | E8: liter | F8: 1000 | G8: ml | H8: =D8/F8 -> 35
A9: B06 | B9: Gula Cair (Simple Syrup) | C9: Pemanis | D9: 15000 | E9: liter | F9: 1000 | G9: ml | H9: =D9/F9 -> 15
A10: B08 | B10: Garam Laut (Sea Salt) | C10: Topping | D10: 20000 | E10: kg | F10: 1000 | G10: gram | H10: =D10/F10 -> 20
A11: B09 | B11: Bubuk Matcha | C11: Bubuk Rasa | D11: 117000 | E11: gram | F11: 100 | G11: gram | H11: =D11/F11 -> 1170
A12: B13 | B12: Es Batu | C12: Es | D12: 3000 | E12: kg | F12: 1000 | G12: gram | H12: =D12/F12 -> 3
A13: B14 | B13: Cup Plastik 12oz + Tutup | C13: Kemasan | D13: 850 | E13: pcs | F13: 1 | G13: pcs | H13: =D13/F13 -> 850
A14: B16 | B14: Sedotan | C14: Kemasan | D14: 100 | E14: pcs | F14: 1 | G14: pcs | H14: =D14/F14 -> 100
A15: B18 | B15: Sirup Butterscotch | C15: Pemanis | D15: 48000 | E15: liter | F15: 1000 | G15: ml | H15: =D15/F15 -> 48
A16: B20 | B16: Krimer Bubuk | C16: Susu | D16: 55000 | E16: kg | F16: 1000 | G16: gram | H16: =D16/F16 -> 55
... A18: B23 | B18: Susu Kental Manis (SKM) | C18: Pemanis | D18: 20000 | E18: liter | F18: 1000 | G18: ml | H18: =D18/F18 -> 20
A20: Catatan:
A21: - Sel berwarna kuning/biru (Harga Beli, Isi per Satuan Beli) adalah asumsi riset pasar per Jul 2026 — silakan sesuaikan dengan harga supplier riil Anda.
A22: - Harga per Satuan Kecil dihitung otomatis dan menjadi acuan seluruh perhitungan resep di sheet 'Resep Menu'.

Sheet Resep Menu
A1: SINGGAH COFFEE — RESEP & TAKARAN MENU
A2: 10 menu terpilih berdasarkan riset tren coffee shop 2026 (kopi susu, espresso based, non-coffee, teh, manual brew).
A4: No | B4: Nama Menu | C4: Kode Bahan | D4: Nama Bahan | E4: Qty per Cup | F4: Satuan | G4: Harga per Satuan Kecil (Rp) | H4: Subtotal Biaya (Rp) | I4: No Menu (helper)
A5: 1 | B5: =INDEX('HPP & Harga Jual'!$B:$B,MATCH(I5,'HPP & Harga Jual'!$A:$A,0)) -> Kopsu Gula Aren | C5: =INDEX('Master Bahan Baku'!$A:$A,MATCH(D5,'Master Bahan Baku'!$B:$B,0)) -> B01 | D5: Kopi Robusta Bubuk/Biji | E5: 15 | F5: gram | G5: =INDEX('Master Bahan Baku'!$H:$H,MATCH(C5,'Master Bahan Baku'!$A:$A,0)) -> 126 | H5: =E5*G5 -> 1890 | I5: =A5 -> 1
B6: =INDEX('HPP & Harga Jual'!$B:$B,MATCH(I6,'HPP & Harga Jual'!$A:$A,0)) -> Kopsu Gula Aren | C6: =INDEX('Master Bahan Baku'!$A:$A,MATCH(D6,'Master Bahan Baku'!$B:$B,0)) -> B03 | D6: Susu Full Cream UHT | E6: 100 | F6: ml | G6: =INDEX('Master Bahan Baku'!$H:$H,MATCH(C6,'Master Bahan Baku'!$A:$A,0)) -> 22 | H6: =E6*G6 -> 2200 | I6: =IF(A6<>"",A6,I5) -> 1
B7: =INDEX('HPP & Harga Jual'!$B:$B,MATCH(I7,'HPP & Harga Jual'!$A:$A,0)) -> Kopsu Gula Aren | C7: =INDEX('Master Bahan Baku'!$A:$A,MATCH(D7,'Master Bahan Baku'!$B:$B,0)) -> B20 | D7: Krimer Bubuk | E7: 25 | F7: gram | G7: =INDEX('Master Bahan Baku'!$H:$H,MATCH(C7,'Master Bahan Baku'!$A:$A,0)) -> 55 | H7: =E7*G7 -> 1375 | I7: =IF(A7<>"",A7,I6) -> 1
B8: =INDEX('HPP & Harga Jual'!$B:$B,MATCH(I8,'HPP & Harga Jual'!$A:$A,0)) -> Kopsu Gula Aren | C8: =INDEX('Master Bahan Baku'!$A:$A,MATCH(D8,'Master Bahan Baku'!$B:$B,0)) -> B05 | D8: Gula Aren Cair (Palm Sugar Syrup) | E8: 30 | F8: ml | G8: =INDEX('Master Bahan Baku'!$H:$H,MATCH(C8,'Master Bahan Baku'!$A:$A,0)) -> 35 | H8: =E8*G8 -> 1050 | I8: =IF(A8<>"",A8,I7) -> 1
B9: =INDEX('HPP & Harga Jual'!$B:$B,MATCH(I9,'HPP & Harga Jual'!$A:$A,0)) -> Kopsu Gula Aren | C9: =INDEX('Master Bahan Baku'!$A:$A,MATCH(D9,'Master Bahan Baku'!$B:$B,0)) -> B13 | D9: Es Batu | E9: 100 | F9: gram | G9: =INDEX('Master Bahan Baku'!$H:$H,MATCH(C9,'Master Bahan Baku'!$A:$A,0)) -> 3 | H9: =E9*G9 -> 300 | I9: =IF(A9<>"",A9,I8) -> 1
B10: =INDEX('HPP & Harga Jual'!$B:$B,MATCH(I10,'HPP & Harga Jual'!$A:$A,0)) -> Kopsu Gula Aren | C10: =INDEX('Master Bahan Baku'!$A:$A,MATCH(D10,'Master Bahan Baku'!$B:$B,0)) -> B14 | D10: Cup Plastik 12oz + Tutup | E10: 1 | F10: pcs | G10: =INDEX('Master Bahan Baku'!$H:$H,MATCH(C10,'Master Bahan Baku'!$A:$A,0)) -> 850 | H10: =E10*G10 -> 850 | I10: =IF(A10<>"",A10,I9) -> 1
B11: =INDEX('HPP & Harga Jual'!$B:$B,MATCH(I11,'HPP & Harga Jual'!$A:$A,0)) -> Kopsu Gula Aren | C11: =INDEX('Master Bahan Baku'!$A:$A,MATCH(D11,'Master Bahan Baku'!$B:$B,0)) -> B16 | D11: Sedotan | E11: 1 | F11: pcs | G11: =INDEX('Master Bahan Baku'!$H:$H,MATCH(C11,'Master Bahan Baku'!$A:$A,0)) -> 100 | H11: =E11*G11 -> 100 | I11: =IF(A11<>"",A11,I10) -> 1
A12: 2 | B12: =INDEX('HPP & Harga Jual'!$B:$B,MATCH(I12,'HPP & Harga Jual'!$A:$A,0)) -> Kopsu Original | C12: =INDEX('Master Bahan Baku'!$A:$A,MATCH(D12,'Master Bahan Baku'!$B:$B,0)) -> B01 | D12: Kopi Robusta Bubuk/Biji | E12: 15 | F12: gram | G12: =INDEX('Master Bahan Baku'!$H:$H,MATCH(C12,'Master Bahan Baku'!$A:$A,0)) -> 126 | H12: =E12*G12 -> 1890 | I12: =IF(A12<>"",A12,I11) -> 2
B13: =INDEX('HPP & Harga Jual'!$B:$B,MATCH(I13,'HPP & Harga Jual'!$A:$A,0)) -> Kopsu Original | C13: =INDEX('Master Bahan Baku'!$A:$A,MATCH(D13,'Master Bahan Baku'!$B:$B,0)) -> B03 | D13: Susu Full Cream UHT | E13: 100 | F13: ml | G13: =INDEX('Master Bahan Baku'!$H:$H,MATCH(C13,'Master Bahan Baku'!$A:$A,0)) -> 22 | H13: =E13*G13 -> 2200 | I13: =IF(A13<>"",A13,I12) -> 2
B14: =INDEX('HPP & Harga Jual'!$B:$B,MATCH(I14,'HPP & Harga Jual'!$A:$A,0)) -> Kopsu Original | C14: =INDEX('Master Bahan Baku'!$A:$A,MATCH(D14,'Master Bahan Baku'!$B:$B,0)) -> B20 | D14: Krimer Bubuk | E14: 25 | F14: gram | G14: =INDEX('Master Bahan Baku'!$H:$H,MATCH(C14,'Master Bahan Baku'!$A:$A,0)) -> 55 | H14: =E14*G14 -> 1375 | I14: =IF(A14<>"",A14,I13) -> 2
B15: =INDEX('HPP & Harga Jual'!$B:$B,MATCH(I15,'HPP & Harga Jual'!$A:$A,0)) -> Kopsu Original | C15: =INDEX('Master Bahan Baku'!$A:$A,MATCH(D15,'Master Bahan Baku'!$B:$B,0)) -> B23 | D15: Susu Kental Manis (SKM) | E15: 25 | F15: ml | G15: =INDEX('Master Bahan Baku'!$H:$H,MATCH(C15,'Master Bahan Baku'!$A:$A,0)) -> 20 | H15: =E15*G15 -> 500 | I15: =IF(A15<>"",A15,I14) -> 2
B16: =INDEX('HPP & Harga Jual'!$B:$B,MATCH(I16,'HPP & Harga Jual'!$A:$A,0)) -> Kopsu Original | C16: =INDEX('Master Bahan Baku'!$A:$A,MATCH(D16,'Master Bahan Baku'!$B:$B,0)) -> B13 | D16: Es Batu | E16: 100 | F16: gram | G16: =INDEX('Master Bahan Baku'!$H:$H,MATCH(C16,'Master Bahan Baku'!$A:$A,0)) -> 3 | H16: =E16*G16 -> 300 | I16: =IF(A16<>"",A16,I15) -> 2
B17: =INDEX('HPP & Harga Jual'!$B:$B,MATCH(I17,'HPP & Harga Jual'!$A:$A,0)) -> Kopsu Original | C17: =INDEX('Master Bahan Baku'!$A:$A,MATCH(D17,'Master Bahan Baku'!$B:$B,0)) -> B14 | D17: Cup Plastik 12oz + Tutup | E17: 1 | F17: pcs | G17: =INDEX('Master Bahan Baku'!$H:$H,MATCH(C17,'Master Bahan Baku'!$A:$A,0)) -> 850 | H17: =E17*G17 -> 850 | I17: =IF(A17<>"",A17,I16) -> 2
B18: =INDEX('HPP & Harga Jual'!$B:$B,MATCH(I18,'HPP & Harga Jual'!$A:$A,0)) -> Kopsu Original | C18: =INDEX('Master Bahan Baku'!$A:$A,MATCH(D18,'Master Bahan Baku'!$B:$B,0)) -> B16 | D18: Sedotan | E18: 1 | F18: pcs | G18: =INDEX('Master Bahan Baku'!$H:$H,MATCH(C18,'Master Bahan Baku'!$A:$A,0)) -> 100 | H18: =E18*G18 -> 100 | I18: =IF(A18<>"",A18,I17) -> 2
A19: 3 | B19: =INDEX('HPP & Harga Jual'!$B:$B,MATCH(I19,'HPP & Harga Jual'!$A:$A,0)) -> Americano (Es) | C19: =INDEX('Master Bahan Baku'!$A:$A,MATCH(D19,'Master Bahan Baku'!$B:$B,0)) -> B01 | D19: Kopi Robusta Bubuk/Biji | E19: 15 | F19: gram | G19: =INDEX('Master Bahan Baku'!$H:$H,MATCH(C19,'Master Bahan Baku'!$A:$A,0)) -> 126 | H19: =E19*G19 -> 1890 | I19: =IF(A19<>"",A19,I18) -> 3
B20: =INDEX('HPP & Harga Jual'!$B:$B,MATCH(I20,'HPP & Harga Jual'!$A:$A,0)) -> Americano (Es) | C20: =INDEX('Master Bahan Baku'!$A:$A,MATCH(D20,'Master Bahan Baku'!$B:$B,0)) -> B06 | D20: Gula Cair (Simple Syrup) | E20: 10 | F20: ml | G20: =INDEX('Master Bahan Baku'!$H:$H,MATCH(C20,'Master Bahan Baku'!$A:$A,0)) -> 15 | H20: =E20*G20 -> 150 | I20: =IF(A20<>"",A20,I19) -> 3
B21: =INDEX('HPP & Harga Jual'!$B:$B,MATCH(I21,'HPP & Harga Jual'!$A:$A,0)) -> Americano (Es) | C21: =INDEX('Master Bahan Baku'!$A:$A,MATCH(D21,'Master Bahan Baku'!$B:$B,0)) -> B13 | D21: Es Batu | E21: 100 | F21: gram | G21: =INDEX('Master Bahan Baku'!$H:$H,MATCH(C21,'Master Bahan Baku'!$A:$A,0)) -> 3 | H21: =E21*G21 -> 300 | I21: =IF(A21<>"",A21,I20) -> 3
B22: =INDEX('HPP & Harga Jual'!$B:$B,MATCH(I22,'HPP & Harga Jual'!$A:$A,0)) -> Americano (Es) | C22: =INDEX('Master Bahan Baku'!$A:$A,MATCH(D22,'Master Bahan Baku'!$B:$B,0)) -> B14 | D22: Cup Plastik 12oz + Tutup | E22: 1 | F22: pcs | G22: =INDEX('Master Bahan Baku'!$H:$H,MATCH(C22,'Master Bahan Baku'!$A:$A,0)) -> 850 | H22: =E22*G22 -> 850 | I22: =IF(A22<>"",A22,I21) -> 3
B23: =INDEX('HPP & Harga Jual'!$B:$B,MATCH(I23,'HPP & Harga Jual'!$A:$A,0)) -> Americano (Es) | C23: =INDEX('Master Bahan Baku'!$A:$A,MATCH(D23,'Master Bahan Baku'!$B:$B,0)) -> B16 | D23: Sedotan | E23: 1 | F23: pcs | G23: =INDEX('Master Bahan Baku'!$H:$H,MATCH(C23,'Master Bahan Baku'!$A:$A,0)) -> 100 | H23: =E23*G23 -> 100 | I23: =IF(A23<>"",A23,I22) -> 3
A24: 4 | B24: =INDEX('HPP & Harga Jual'!$B:$B,MATCH(I24,'HPP & Harga Jual'!$A:$A,0)) -> Cappuccino (Panas) | C24: =INDEX('Master Bahan Baku'!$A:$A,MATCH(D24,'Master Bahan Baku'!$B:$B,0)) -> B02 | D24: Kopi Blend Bubuk/Biji | E24: 18 | F24: gram | G24: =INDEX('Master Bahan Baku'!$H:$H,MATCH(C24,'Master Bahan Baku'!$A:$A,0)) -> 200 | H24: =E24*G24 -> 3600 | I24: =IF(A24<>"",A24,I23) -> 4
B25: =INDEX('HPP & Harga Jual'!$B:$B,MATCH(I25,'HPP & Harga Jual'!$A:$A,0)) -> Cappuccino (Panas) | C25: =INDEX('Master Bahan Baku'!$A:$A,MATCH(D25,'Master Bahan Baku'!$B:$B,0)) -> B03 | D25: Susu Full Cream UHT | E25: 100 | F25: ml | G25: =INDEX('Master Bahan Baku'!$H:$H,MATCH(C25,'Master Bahan Baku'!$A:$A,0)) -> 22 | H25: =E25*G25 -> 2200 | I25: =IF(A25<>"",A25,I24) -> 4
B26: =INDEX('HPP & Harga Jual'!$B:$B,MATCH(I26,'HPP & Harga Jual'!$A:$A,0)) -> Cappuccino (Panas) | C26: =INDEX('Master Bahan Baku'!$A:$A,MATCH(D26,'Master Bahan Baku'!$B:$B,0)) -> B20 | D26: Krimer Bubuk | E26: 25 | F26: gram | G26: =INDEX('Master Bahan Baku'!$H:$H,MATCH(C26,'Master Bahan Baku'!$A:$A,0)) -> 55 | H26: =E26*G26 -> 1375 | I26: =IF(A26<>"",A26,I25) -> 4
B27: =INDEX('HPP & Harga Jual'!$B:$B,MATCH(I27,'HPP & Harga Jual'!$A:$A,0)) -> Cappuccino (Panas) | C27: =INDEX('Master Bahan Baku'!$A:$A,MATCH(D27,'Master Bahan Baku'!$B:$B,0)) -> B14 | D27: Cup Plastik 12oz + Tutup | E27: 1 | F27: pcs | G27: =INDEX('Master Bahan Baku'!$H:$H,MATCH(C27,'Master Bahan Baku'!$A:$A,0)) -> 850 | H27: =E27*G27 -> 850 | I27: =IF(A27<>"",A27,I26) -> 4
A28: 5 | B28: =INDEX('HPP & Harga Jual'!$B:$B,MATCH(I28,'HPP & Harga Jual'!$A:$A,0)) -> Matcha | C28: =INDEX('Master Bahan Baku'!$A:$A,MATCH(D28,'Master Bahan Baku'!$B:$B,0)) -> B09 | D28: Bubuk Matcha | E28: 8 | F28: gram | G28: =INDEX('Master Bahan Baku'!$H:$H,MATCH(C28,'Master Bahan Baku'!$A:$A,0)) -> 1170 | H28: =E28*G28 -> 9360 | I28: =IF(A28<>"",A28,I27) -> 5
B29: =INDEX('HPP & Harga Jual'!$B:$B,MATCH(I29,'HPP & Harga Jual'!$A:$A,0)) -> Matcha | C29: =INDEX('Master Bahan Baku'!$A:$A,MATCH(D29,'Master Bahan Baku'!$B:$B,0)) -> B03 | D29: Susu Full Cream UHT | E29: 100 | F29: ml | G29: =INDEX('Master Bahan Baku'!$H:$H,MATCH(C29,'Master Bahan Baku'!$A:$A,0)) -> 22 | H29: =E29*G29 -> 2200 | I29: =IF(A29<>"",A29,I28) -> 5
B30: =INDEX('HPP & Harga Jual'!$B:$B,MATCH(I30,'HPP & Harga Jual'!$A:$A,0)) -> Matcha | C30: =INDEX('Master Bahan Baku'!$A:$A,MATCH(D30,'Master Bahan Baku'!$B:$B,0)) -> B20 | D30: Krimer Bubuk | E30: 10 | F30: gram | G30: =INDEX('Master Bahan Baku'!$H:$H,MATCH(C30,'Master Bahan Baku'!$A:$A,0)) -> 55 | H30: =E30*G30 -> 550 | I30: =IF(A30<>"",A30,I29) -> 5
B31: =INDEX('HPP & Harga Jual'!$B:$B,MATCH(I31,'HPP & Harga Jual'!$A:$A,0)) -> Matcha | C31: =INDEX('Master Bahan Baku'!$A:$A,MATCH(D31,'Master Bahan Baku'!$B:$B,0)) -> B06 | D31: Gula Cair (Simple Syrup) | E31: 20 | F31: ml | G31: =INDEX('Master Bahan Baku'!$H:$H,MATCH(C31,'Master Bahan Baku'!$A:$A,0)) -> 15 | H31: =E31*G31 -> 300 | I31: =IF(A31<>"",A31,I30) -> 5
B32: =INDEX('HPP & Harga Jual'!$B:$B,MATCH(I32,'HPP & Harga Jual'!$A:$A,0)) -> Matcha | C32: =INDEX('Master Bahan Baku'!$A:$A,MATCH(D32,'Master Bahan Baku'!$B:$B,0)) -> B13 | D32: Es Batu | E32: 100 | F32: gram | G32: =INDEX('Master Bahan Baku'!$H:$H,MATCH(C32,'Master Bahan Baku'!$A:$A,0)) -> 3 | H32: =E32*G32 -> 300 | I32: =IF(A32<>"",A32,I31) -> 5
B33: =INDEX('HPP & Harga Jual'!$B:$B,MATCH(I33,'HPP & Harga Jual'!$A:$A,0)) -> Matcha | C33: =INDEX('Master Bahan Baku'!$A:$A,MATCH(D33,'Master Bahan Baku'!$B:$B,0)) -> B14 | D33: Cup Plastik 12oz + Tutup | E33: 1 | F33: pcs | G33: =INDEX('Master Bahan Baku'!$H:$H,MATCH(C33,'Master Bahan Baku'!$A:$A,0)) -> 850 | H33: =E33*G33 -> 850 | I33: =IF(A33<>"",A33,I32) -> 5
B34: =INDEX('HPP & Harga Jual'!$B:$B,MATCH(I34,'HPP & Harga Jual'!$A:$A,0)) -> Matcha | C34: =INDEX('Master Bahan Baku'!$A:$A,MATCH(D34,'Master Bahan Baku'!$B:$B,0)) -> B16 | D34: Sedotan | E34: 1 | F34: pcs | G34: =INDEX('Master Bahan Baku'!$H:$H,MATCH(C34,'Master Bahan Baku'!$A:$A,0)) -> 100 | H34: =E34*G34 -> 100 | I34: =IF(A34<>"",A34,I33) -> 5
A35: 6 | B35: =INDEX('HPP & Harga Jual'!$B:$B,MATCH(I35,'HPP & Harga Jual'!$A:$A,0)) -> Kopsu Singgah Aren | C35: =INDEX('Master Bahan Baku'!$A:$A,MATCH(D35,'Master Bahan Baku'!$B:$B,0)) -> B02 | D35: Kopi Blend Bubuk/Biji | E35: 18 | F35: gram | G35: =INDEX('Master Bahan Baku'!$H:$H,MATCH(C35,'Master Bahan Baku'!$A:$A,0)) -> 200 | H35: =E35*G35 -> 3600 | I35: =IF(A35<>"",A35,I34) -> 6
B36: =INDEX('HPP & Harga Jual'!$B:$B,MATCH(I36,'HPP & Harga Jual'!$A:$A,0)) -> Kopsu Singgah Aren | C36: =INDEX('Master Bahan Baku'!$A:$A,MATCH(D36,'Master Bahan Baku'!$B:$B,0)) -> B03 | D36: Susu Full Cream UHT | E36: 100 | F36: ml | G36: =INDEX('Master Bahan Baku'!$H:$H,MATCH(C36,'Master Bahan Baku'!$A:$A,0)) -> 22 | H36: =E36*G36 -> 2200 | I36: =IF(A36<>"",A36,I35) -> 6
B37: =INDEX('HPP & Harga Jual'!$B:$B,MATCH(I37,'HPP & Harga Jual'!$A:$A,0)) -> Kopsu Singgah Aren | C37: =INDEX('Master Bahan Baku'!$A:$A,MATCH(D37,'Master Bahan Baku'!$B:$B,0)) -> B20 | D37: Krimer Bubuk | E37: 25 | F37: gram | G37: =INDEX('Master Bahan Baku'!$H:$H,MATCH(C37,'Master Bahan Baku'!$A:$A,0)) -> 55 | H37: =E37*G37 -> 1375 | I37: =IF(A37<>"",A37,I36) -> 6
B38: =INDEX('HPP & Harga Jual'!$B:$B,MATCH(I38,'HPP & Harga Jual'!$A:$A,0)) -> Kopsu Singgah Aren | C38: =INDEX('Master Bahan Baku'!$A:$A,MATCH(D38,'Master Bahan Baku'!$B:$B,0)) -> B05 | D38: Gula Aren Cair (Palm Sugar Syrup) | E38: 30 | F38: ml | G38: =INDEX('Master Bahan Baku'!$H:$H,MATCH(C38,'Master Bahan Baku'!$A:$A,0)) -> 35 | H38: =E38*G38 -> 1050 | I38: =IF(A38<>"",A38,I37) -> 6
B39: =INDEX('HPP & Harga Jual'!$B:$B,MATCH(I39,'HPP & Harga Jual'!$A:$A,0)) -> Kopsu Singgah Aren | C39: =INDEX('Master Bahan Baku'!$A:$A,MATCH(D39,'Master Bahan Baku'!$B:$B,0)) -> B08 | D39: Garam Laut (Sea Salt) | E39: 1 | F39: gram | G39: =INDEX('Master Bahan Baku'!$H:$H,MATCH(C39,'Master Bahan Baku'!$A:$A,0)) -> 20 | H39: =E39*G39 -> 20 | I39: =IF(A39<>"",A39,I38) -> 6
B40: =INDEX('HPP & Harga Jual'!$B:$B,MATCH(I40,'HPP & Harga Jual'!$A:$A,0)) -> Kopsu Singgah Aren | C40: =INDEX('Master Bahan Baku'!$A:$A,MATCH(D40,'Master Bahan Baku'!$B:$B,0)) -> B13 | D40: Es Batu | E40: 100 | F40: gram | G40: =INDEX('Master Bahan Baku'!$H:$H,MATCH(C40,'Master Bahan Baku'!$A:$A,0)) -> 3 | H40: =E40*G40 -> 300 | I40: =IF(A40<>"",A40,I39) -> 6
B41: =INDEX('HPP & Harga Jual'!$B:$B,MATCH(I41,'HPP & Harga Jual'!$A:$A,0)) -> Kopsu Singgah Aren | C41: =INDEX('Master Bahan Baku'!$A:$A,MATCH(D41,'Master Bahan Baku'!$B:$B,0)) -> B14 | D41: Cup Plastik 12oz + Tutup | E41: 1 | F41: pcs | G41: =INDEX('Master Bahan Baku'!$H:$H,MATCH(C41,'Master Bahan Baku'!$A:$A,0)) -> 850 | H41: =E41*G41 -> 850 | I41: =IF(A41<>"",A41,I40) -> 6
...

Sheet Kebutuhan Stok
A1: SINGGAH COFFEE — KEBUTUHAN STOK BAHAN BAKU (BERDASARKAN TARGET CUP)
A2: Atur "Target Jumlah Cup" (sel biru, bagian A) untuk tiap menu. Kebutuhan bahan baku per menu (bagian B), total belanja (bagian C), dan rata-rata cup/hari untuk BEP terhitung otomatis.
A4: A. TARGET PRODUKSI PER MENU (EDIT SEL BIRU "Target Jumlah Cup")
A6: ='HPP & Harga Jual'!A5 -> 1 | B6: ='HPP & Harga Jual'!B5 -> Kopsu Gula Aren | G6: 50
A7: ='HPP & Harga Jual'!A6 -> 2 | B7: ='HPP & Harga Jual'!B6 -> Kopsu Original | G7: 50
A8: ='HPP & Harga Jual'!A7 -> 3 | B8: ='HPP & Harga Jual'!B7 -> Americano (Es) | G8: 50
A9: ='HPP & Harga Jual'!A8 -> 4 | B9: ='HPP & Harga Jual'!B8 -> Cappuccino (Panas) | G9: 50
A10: ='HPP & Harga Jual'!A9 -> 5 | B10: ='HPP & Harga Jual'!B9 -> Matcha | G10: 50
A11: ='HPP & Harga Jual'!A10 -> 6 | B11: ='HPP & Harga Jual'!B10 -> Kopsu Singgah Aren | G11: 50
A12: ='HPP & Harga Jual'!A11 -> 7 | B12: ='HPP & Harga Jual'!B11 -> Butterscotch Latte | G12: 50
A13: ='HPP & Harga Jual'!A12 -> 8 | B13: ='HPP & Harga Jual'!B12 -> Kopsu Singgah | G13: 50
A14: ='HPP & Harga Jual'!A13 -> 9 | B14: ='HPP & Harga Jual'!B13 -> Oatside Signature | G14: 50
A15: ='HPP & Harga Jual'!A14 -> 10 | B15: ='HPP & Harga Jual'!B14 -> Oatside Signature Gula Aren | G15: 50
A16: Catatan: kolom "Nama Menu" & "No" mengikuti sheet 'HPP & Harga Jual' secara otomatis — jangan diedit manual di sini.
A18: RINGKASAN TARGET PRODUKSI HARIAN — SUMBER TUNGGAL UNTUK SHEET BEP
A19: Total Target Cup (Semua Menu, dari Bagian A) | G19: =SUM(G6:G15) -> 500 | I19: cup
A20: Estimasi Periode Penjualan/Stok Habis (Hari) — EDIT SEL BIRU | G20: 10 | I20: hari (mis. 30 = target habis dalam 1 bulan)
A21: Rata-rata Cup Terjual per Hari -> dipakai otomatis di sheet BEP | G21: =IF(G20=0,0,ROUNDUP(G19/G20,0)) -> 50 | I21: cup/hari
A23: B. DETAIL KEBUTUHAN BAHAN PER MENU (OTOMATIS DARI SHEET 'RESEP MENU' x TARGET CUP)
A24: No | B24: Nama Menu | C24: Kode Bahan | D24: Nama Bahan | E24: Qty/Cup | F24: Satuan | G24: Target Cup | H24: Total Kebutuhan | I24: Satuan Beli | J24: Kebutuhan (Satuan Beli) | K24: Estimasi Biaya (Rp)
A25: =IF('Resep Menu'!A5="","",'Resep Menu'!A5) -> 1 | B25: ='Resep Menu'!B5 -> Kopsu Gula Aren | C25: ='Resep Menu'!C5 -> B01 | D25: ='Resep Menu'!D5 -> Kopi Robusta Bubuk/Biji | E25: ='Resep Menu'!E5 -> 15 | F25: ='Resep Menu'!F5 -> gram | G25: =INDEX($G$6:$G$15,MATCH(B25,$B$6:$B$15,0)) -> 50 | H25: =E25*G25 -> 750 | I25: =INDEX('Master Bahan Baku'!$E$5:$E$18,MATCH(C25,'Master Bahan Baku'!$A$5:$A$18,0)) -> kg | J25: =IFERROR(H25/INDEX('Master Bahan Baku'!$F$5:$F$18,MATCH(C25,'Master Bahan Baku'!$A$5:$A$18,0)),0) -> 0.75 | K25: =H25*INDEX('Master Bahan Baku'!$H$5:$H$18,MATCH(C25,'Master Bahan Baku'!$A$5:$A$18,0)) -> 94500
A26: =IF('Resep Menu'!A6="","",'Resep Menu'!A6) | B26: ='Resep Menu'!B6 -> Kopsu Gula Aren | C26: ='Resep Menu'!C6 -> B03 | D26: ='Resep Menu'!D6 -> Susu Full Cream UHT | E26: ='Resep Menu'!E6 -> 100 | F26: ='Resep Menu'!F6 -> ml | G26: =INDEX($G$6:$G$15,MATCH(B26,$B$6:$B$15,0)) -> 50 | H26: =E26*G26 -> 5000 | I26: =INDEX('Master Bahan Baku'!$E$5:$E$18,MATCH(C26,'Master Bahan Baku'!$A$5:$A$18,0)) -> liter | J26: =IFERROR(H26/INDEX('Master Bahan Baku'!$F$5:$F$18,MATCH(C26,'Master Bahan Baku'!$A$5:$A$18,0)),0) -> 5 | K26: =H26*INDEX('Master Bahan Baku'!$H$5:$H$18,MATCH(C26,'Master Bahan Baku'!$A$5:$A$18,0)) -> 110000
A27: =IF('Resep Menu'!A7="","",'Resep Menu'!A7) | B27: ='Resep Menu'!B7 -> Kopsu Gula Aren | C27: ='Resep Menu'!C7 -> B20 | D27: ='Resep Menu'!D7 -> Krimer Bubuk | E27: ='Resep Menu'!E7 -> 25 | F27: ='Resep Menu'!F7 -> gram | G27: =INDEX($G$6:$G$15,MATCH(B27,$B$6:$B$15,0)) -> 50 | H27: =E27*G27 -> 1250 | I27: =INDEX('Master Bahan Baku'!$E$5:$E$18,MATCH(C27,'Master Bahan Baku'!$A$5:$A$18,0)) -> kg | J27: =IFERROR(H27/INDEX('Master Bahan Baku'!$F$5:$F$18,MATCH(C27,'Master Bahan Baku'!$A$5:$A$18,0)),0) -> 1.25 | K27: =H27*INDEX('Master Bahan Baku'!$H$5:$H$18,MATCH(C27,'Master Bahan Baku'!$A$5:$A$18,0)) -> 68750
A28: =IF('Resep Menu'!A8="","",'Resep Menu'!A8) | B28: ='Resep Menu'!B8 -> Kopsu Gula Aren | C28: ='Resep Menu'!C8 -> B05 | D28: ='Resep Menu'!D8 -> Gula Aren Cair (Palm Sugar Syrup) | E28: ='Resep Menu'!E8 -> 30 | F28: ='Resep Menu'!F8 -> ml | G28: =INDEX($G$6:$G$15,MATCH(B28,$B$6:$B$15,0)) -> 50 | H28: =E28*G28 -> 1500 | I28: =INDEX('Master Bahan Baku'!$E$5:$E$18,MATCH(C28,'Master Bahan Baku'!$A$5:$A$18,0)) -> liter | J28: =IFERROR(H28/INDEX('Master Bahan Baku'!$F$5:$F$18,MATCH(C28,'Master Bahan Baku'!$A$5:$A$18,0)),0) -> 1.5 | K28: =H28*INDEX('Master Bahan Baku'!$H$5:$H$18,MATCH(C28,'Master Bahan Baku'!$A$5:$A$18,0)) -> 52500
A29: =IF('Resep Menu'!A9="","",'Resep Menu'!A9) | B29: ='Resep Menu'!B9 -> Kopsu Gula Aren | C29: ='Resep Menu'!C9 -> B13 | D29: ='Resep Menu'!D9 -> Es Batu | E29: ='Resep Menu'!E9 -> 100 | F29: ='Resep Menu'!F9 -> gram | G29: =INDEX($G$6:$G$15,MATCH(B29,$B$6:$B$15,0)) -> 50 | H29: =E29*G29 -> 5000 | I29: =INDEX('Master Bahan Baku'!$E$5:$E$18,MATCH(C29,'Master Bahan Baku'!$A$5:$A$18,0)) -> kg | J29: =IFERROR(H29/INDEX('Master Bahan Baku'!$F$5:$F$18,MATCH(C29,'Master Bahan Baku'!$A$5:$A$18,0)),0) -> 5 | K29: =H29*INDEX('Master Bahan Baku'!$H$5:$H$18,MATCH(C29,'Master Bahan Baku'!$A$5:$A$18,0)) -> 15000
A30: =IF('Resep Menu'!A10="","",'Resep Menu'!A10) | B30: ='Resep Menu'!B10 -> Kopsu Gula Aren | C30: ='Resep Menu'!C10 -> B14 | D30: ='Resep Menu'!D10 -> Cup Plastik 12oz + Tutup | E30: ='Resep Menu'!E10 -> 1 | F30: ='Resep Menu'!F10 -> pcs | G30: =INDEX($G$6:$G$15,MATCH(B30,$B$6:$B$15,0)) -> 50 | H30: =E30*G30 -> 50 | I30: =INDEX('Master Bahan Baku'!$E$5:$E$18,MATCH(C30,'Master Bahan Baku'!$A$5:$A$18,0)) -> pcs | J30: =IFERROR(H30/INDEX('Master Bahan Baku'!$F$5:$F$18,MATCH(C30,'Master Bahan Baku'!$A$5:$A$18,0)),0) -> 50 | K30: =H30*INDEX('Master Bahan Baku'!$H$5:$H$18,MATCH(C30,'Master Bahan Baku'!$A$5:$A$18,0)) -> 42500
A31: =IF('Resep Menu'!A11="","",'Resep Menu'!A11) | B31: ='Resep Menu'!B11 -> Kopsu Gula Aren | C31: ='Resep Menu'!C11 -> B16 | D31: ='Resep Menu'!D11 -> Sedotan | E31: ='Resep Menu'!E11 -> 1 | F31: ='Resep Menu'!F11 -> pcs | G31: =INDEX($G$6:$G$15,MATCH(B31,$B$6:$B$15,0)) -> 50 | H31: =E31*G31 -> 50 | I31: =INDEX('Master Bahan Baku'!$E$5:$E$18,MATCH(C31,'Master Bahan Baku'!$A$5:$A$18,0)) -> pcs | J31: =IFERROR(H31/INDEX('Master Bahan Baku'!$F$5:$F$18,MATCH(C31,'Master Bahan Baku'!$A$5:$A$18,0)),0) -> 50 | K31: =H31*INDEX('Master Bahan Baku'!$H$5:$H$18,MATCH(C31,'Master Bahan Baku'!$A$5:$A$18,0)) -> 5000
A32: =IF('Resep Menu'!A12="","",'Resep Menu'!A12) -> 2 | B32: ='Resep Menu'!B12 -> Kopsu Original | C32: ='Resep Menu'!C12 -> B01 | D32: ='Resep Menu'!D12 -> Kopi Robusta Bubuk/Biji | E32: ='Resep Menu'!E12 -> 15 | F32: ='Resep Menu'!F12 -> gram | G32: =INDEX($G$6:$G$15,MATCH(B32,$B$6:$B$15,0)) -> 50 | H32: =E32*G32 -> 750 | I32: =INDEX('Master Bahan Baku'!$E$5:$E$18,MATCH(C32,'Master Bahan Baku'!$A$5:$A$18,0)) -> kg | J32: =IFERROR(H32/INDEX('Master Bahan Baku'!$F$5:$F$18,MATCH(C32,'Master Bahan Baku'!$A$5:$A$18,0)),0) -> 0.75 | K32: =H32*INDEX('Master Bahan Baku'!$H$5:$H$18,MATCH(C32,'Master Bahan Baku'!$A$5:$A$18,0)) -> 94500
A33: =IF('Resep Menu'!A13="","",'Resep Menu'!A13) | B33: ='Resep Menu'!B13 -> Kopsu Original | C33: ='Resep Menu'!C13 -> B03 | D33: ='Resep Menu'!D13 -> Susu Full Cream UHT | E33: ='Resep Menu'!E13 -> 100 | F33: ='Resep Menu'!F13 -> ml | G33: =INDEX($G$6:$G$15,MATCH(B33,$B$6:$B$15,0)) -> 50 | H33: =E33*G33 -> 5000 | I33: =INDEX('Master Bahan Baku'!$E$5:$E$18,MATCH(C33,'Master Bahan Baku'!$A$5:$A$18,0)) -> liter | J33: =IFERROR(H33/INDEX('Master Bahan Baku'!$F$5:$F$18,MATCH(C33,'Master Bahan Baku'!$A$5:$A$18,0)),0) -> 5 | K33: =H33*INDEX('Master Bahan Baku'!$H$5:$H$18,MATCH(C33,'Master Bahan Baku'!$A$5:$A$18,0)) -> 110000
A34: =IF('Resep Menu'!A14="","",'Resep Menu'!A14) | B34: ='Resep Menu'!B14 -> Kopsu Original | C34: ='Resep Menu'!C14 -> B20 | D34: ='Resep Menu'!D14 -> Krimer Bubuk | E34: ='Resep Menu'!E14 -> 25 | F34: ='Resep Menu'!F14 -> gram | G34: =INDEX($G$6:$G$15,MATCH(B34,$B$6:$B$15,0)) -> 50 | H34: =E34*G34 -> 1250 | I34: =INDEX('Master Bahan Baku'!$E$5:$E$18,MATCH(C34,'Master Bahan Baku'!$A$5:$A$18,0)) -> kg | J34: =IFERROR(H34/INDEX('Master Bahan Baku'!$F$5:$F$18,MATCH(C34,'Master Bahan Baku'!$A$5:$A$18,0)),0) -> 1.25 | K34: =H34*INDEX('Master Bahan Baku'!$H$5:$H$18,MATCH(C34,'Master Bahan Baku'!$A$5:$A$18,0)) -> 68750
A35: =IF('Resep Menu'!A15="","",'Resep Menu'!A15) | B35: ='Resep Menu'!B15 -> Kopsu Original | C35: ='Resep Menu'!C15 -> B23 | D35: ='Resep Menu'!D15 -> Susu Kental Manis (SKM) | E35: ='Resep Menu'!E15 -> 25 | F35: ='Resep Menu'!F15 -> ml | G35: =INDEX($G$6:$G$15,MATCH(B35,$B$6:$B$15,0)) -> 50 | H35: =E35*G35 -> 1250 | I35: =INDEX('Master Bahan Baku'!$E$5:$E$18,MATCH(C35,'Master Bahan Baku'!$A$5:$A$18,0)) -> liter | J35: =IFERROR(H35/INDEX('Master Bahan Baku'!$F$5:$F$18,MATCH(C35,'Master Bahan Baku'!$A$5:$A$18,0)),0) -> 1.25 | K35: =H35*INDEX('Master Bahan Baku'!$H$5:$H$18,MATCH(C35,'Master Bahan Baku'!$A$5:$A$18,0)) -> 25000
A36: =IF('Resep Menu'!A16="","",'Resep Menu'!A16) | B36: ='Resep Menu'!B16 -> Kopsu Original | C36: ='Resep Menu'!C16 -> B13 | D36: ='Resep Menu'!D16 -> Es Batu | E36: ='Resep Menu'!E16 -> 100 | F36: ='Resep Menu'!F16 -> gram | G36: =INDEX($G$6:$G$15,MATCH(B36,$B$6:$B$15,0)) -> 50 | H36: =E36*G36 -> 5000 | I36: =INDEX('Master Bahan Baku'!$E$5:$E$18,MATCH(C36,'Master Bahan Baku'!$A$5:$A$18,0)) -> kg | J36: =IFERROR(H36/INDEX('Master Bahan Baku'!$F$5:$F$18,MATCH(C36,'Master Bahan Baku'!$A$5:$A$18,0)),0) -> 5 | K36: =H36*INDEX('Master Bahan Baku'!$H$5:$H$18,MATCH(C36,'Master Bahan Baku'!$A$5:$A$18,0)) -> 15000
... A88: =IF('Resep Menu'!A68="","",'Resep Menu'!A68) | B88: ='Resep Menu'!B68 -> Oatside Signature Gula Aren | C88: ='Resep Menu'!C68 -> B16 | D88: ='Resep Menu'!D68 -> Sedotan | E88: ='Resep Menu'!E68 -> 1 | F88: ='Resep Menu'!F68 -> pcs | G88: =INDEX($G$6:$G$15,MATCH(B88,$B$6:$B$15,0)) -> 50 | H88: =E88*G88 -> 50 | I88: =INDEX('Master Bahan Baku'!$E$5:$E$18,MATCH(C88,'Master Bahan Baku'!$A$5:$A$18,0)) -> pcs | J88: =IFERROR(H88/INDEX('Master Bahan Baku'!$F$5:$F$18,MATCH(C88,'Master Bahan Baku'!$A$5:$A$18,0)),0) -> 50 | K88: =H88*INDEX('Master Bahan Baku'!$H$5:$H$18,MATCH(C88,'Master Bahan Baku'!$A$5:$A$18,0)) -> 5000
A90: C. RINGKASAN TOTAL BELANJA BAHAN BAKU (SEMUA MENU DIGABUNG)
A91: Kode | B91: Nama Bahan | C91: Kategori | D91: Total Kebutuhan | E91: Satuan Kecil | F91: Satuan Beli | G91: Isi/Satuan Beli | H91: Belanja (Satuan Beli, dibulatkan ke atas) | J91: Estimasi Biaya (Rp)
A92: ='Master Bahan Baku'!A5 -> B01 | B92: ='Master Bahan Baku'!B5 -> Kopi Robusta Bubuk/Biji | C92: ='Master Bahan Baku'!C5 -> Kopi | D92: =SUMIF($C$25:$C$150,A92,$H$25:$H$150) -> 2250 | E92: ='Master Bahan Baku'!G5 -> gram | F92: ='Master Bahan Baku'!E5 -> kg | G92: ='Master Bahan Baku'!F5 -> 1000 | H92: =IF(G92=0,0,ROUNDUP(D92/G92,2)) -> 2.25 | J92: =SUMIF($C$25:$C$150,A92,$K$25:$K$150) -> 283500
A93: ='Master Bahan Baku'!A6 -> B02 | B93: ='Master Bahan Baku'!B6 -> Kopi Blend Bubuk/Biji | C93: ='Master Bahan Baku'!C6 -> Kopi | D93: =SUMIF($C$25:$C$150,A93,$H$25:$H$150) -> 5100 | E93: ='Master Bahan Baku'!G6 -> gram | F93: ='Master Bahan Baku'!E6 -> kg | G93: ='Master Bahan Baku'!F6 -> 1000 | H93: =IF(G93=0,0,ROUNDUP(D93/G93,2)) -> 5.1 | J93: =SUMIF($C$25:$C$150,A93,$K$25:$K$150) -> 1020000
A94: ='Master Bahan Baku'!A7 -> B03 | B94: ='Master Bahan Baku'!B7 -> Susu Full Cream UHT | C94: ='Master Bahan Baku'!C7 -> Susu | D94: =SUMIF($C$25:$C$150,A94,$H$25:$H$150) -> 35000 | E94: ='Master Bahan Baku'!G7 -> ml | F94: ='Master Bahan Baku'!E7 -> liter | G94: ='Master Bahan Baku'!F7 -> 1000 | H94: =IF(G94=0,0,ROUNDUP(D94/G94,2)) -> 35 | J94: =SUMIF($C$25:$C$150,A94,$K$25:$K$150) -> 770000
A95: ='Master Bahan Baku'!A8 -> B05 | B95: ='Master Bahan Baku'!B8 -> Gula Aren Cair (Palm Sugar Syrup) | C95: ='Master Bahan Baku'!C8 -> Pemanis | D95: =SUMIF($C$25:$C$150,A95,$H$25:$H$150) -> 4500 | E95: ='Master Bahan Baku'!G8 -> ml | F95: ='Master Bahan Baku'!E8 -> liter | G95: ='Master Bahan Baku'!F8 -> 1000 | H95: =IF(G95=0,0,ROUNDUP(D95/G95,2)) -> 4.5 | J95: =SUMIF($C$25:$C$150,A95,$K$25:$K$150) -> 157500
A96: ='Master Bahan Baku'!A9 -> B06 | B96: ='Master Bahan Baku'!B9 -> Gula Cair (Simple Syrup) | C96: ='Master Bahan Baku'!C9 -> Pemanis | D96: =SUMIF($C$25:$C$150,A96,$H$25:$H$150) -> 1500 | E96: ='Master Bahan Baku'!G9 -> ml | F96: ='Master Bahan Baku'!E9 -> liter | G96: ='Master Bahan Baku'!F9 -> 1000 | H96: =IF(G96=0,0,ROUNDUP(D96/G96,2)) -> 1.5 | J96: =SUMIF($C$25:$C$150,A96,$K$25:$K$150) -> 22500
...

Sheet HPP & Harga Jual
A1: SINGGAH COFFEE — HPP & HARGA JUAL
A2: Food cost dihitung otomatis dari sheet 'Resep Menu'. Sel biru (Biaya Operasional/Cup & Target Food Cost %) boleh disesuaikan.
A4: No | B4: Nama Menu | C4: Biaya Bahan Baku/Food Cost (Rp) | D4: Biaya Operasional per Cup (Rp) | E4: Total HPP (Rp) | F4: Target Food Cost % | G4: Harga Jual Disarankan (Rp) | H4: Harga Jual Dibulatkan (Rp) | I4: Margin per Cup (Rp) | J4: Margin %
A5: 1 | B5: Kopsu Gula Aren | C5: =SUMIF('Resep Menu'!$B:$B,B5,'Resep Menu'!$H:$H) -> 7765 | D5: 4000 | E5: =C5+D5 -> 11765 | F5: 0.8 | G5: =E5/F5 -> 14706.25 | H5: =ROUND(G5/500,0)*500 -> 14500 | I5: =H5-E5 -> 2735 | J5: =I5/H5 -> 0.18862069
A6: 2 | B6: Kopsu Original | C6: =SUMIF('Resep Menu'!$B:$B,B6,'Resep Menu'!$H:$H) -> 7215 | D6: 4000 | E6: =C6+D6 -> 11215 | F6: 0.8 | G6: =E6/F6 -> 14018.75 | H6: =ROUND(G6/500,0)*500 -> 14000 | I6: =H6-E6 -> 2785 | J6: =I6/H6 -> 0.19892857
A7: 3 | B7: Americano (Es) | C7: =SUMIF('Resep Menu'!$B:$B,B7,'Resep Menu'!$H:$H) -> 3290 | D7: 4000 | E7: =C7+D7 -> 7290 | F7: 0.8 | G7: =E7/F7 -> 9112.5 | H7: =ROUND(G7/500,0)*500 -> 9000 | I7: =H7-E7 -> 1710 | J7: =I7/H7 -> 0.19
A8: 4 | B8: Cappuccino (Panas) | C8: =SUMIF('Resep Menu'!$B:$B,B8,'Resep Menu'!$H:$H) -> 8025 | D8: 4000 | E8: =C8+D8 -> 12025 | F8: 0.8 | G8: =E8/F8 -> 15031.25 | H8: =ROUND(G8/500,0)*500 -> 15000 | I8: =H8-E8 -> 2975 | J8: =I8/H8 -> 0.19833333
A9: 5 | B9: Matcha | C9: =SUMIF('Resep Menu'!$B:$B,B9,'Resep Menu'!$H:$H) -> 13660 | D9: 4000 | E9: =C9+D9 -> 17660 | F9: 0.8 | G9: =E9/F9 -> 22075 | H9: =ROUND(G9/500,0)*500 -> 22000 | I9: =H9-E9 -> 4340 | J9: =I9/H9 -> 0.19727273
A10: 6 | B10: Kopsu Singgah Aren | C10: =SUMIF('Resep Menu'!$B:$B,B10,'Resep Menu'!$H:$H) -> 9495 | D10: 4000 | E10: =C10+D10 -> 13495 | F10: 0.8 | G10: =E10/F10 -> 16868.75 | H10: =ROUND(G10/500,0)*500 -> 17000 | I10: =H10-E10 -> 3505 | J10: =I10/H10 -> 0.20617647
A11: 7 | B11: Butterscotch Latte | C11: =SUMIF('Resep Menu'!$B:$B,B11,'Resep Menu'!$H:$H) -> 9625 | D11: 4000 | E11: =C11+D11 -> 13625 | F11: 0.8 | G11: =E11/F11 -> 17031.25 | H11: =ROUND(G11/500,0)*500 -> 17000 | I11: =H11-E11 -> 3375 | J11: =I11/H11 -> 0.19852941
A12: 8 | B12: Kopsu Singgah | C12: =SUMIF('Resep Menu'!$B:$B,B12,'Resep Menu'!$H:$H) -> 8825 | D12: 4000 | E12: =C12+D12 -> 12825 | F12: 0.8 | G12: =E12/F12 -> 16031.25 | H12: =ROUND(G12/500,0)*500 -> 16000 | I12: =H12-E12 -> 3175 | J12: =I12/H12 -> 0.1984375
A13: 9 | B13: Oatside Signature | C13: =SUMIF('Resep Menu'!$B:$B,B13,'Resep Menu'!$H:$H) -> 8450 | D13: 4000 | E13: =C13+D13 -> 12450 | F13: 0.8 | G13: =E13/F13 -> 15562.5 | H13: =ROUND(G13/500,0)*500 -> 15500 | I13: =H13-E13 -> 3050 | J13: =I13/H13 -> 0.19677419
A14: 10 | B14: Oatside Signature Gula Aren | C14: =SUMIF('Resep Menu'!$B:$B,B14,'Resep Menu'!$H:$H) -> 9100 | D14: 4000 | E14: =C14+D14 -> 13100 | F14: 0.8 | G14: =E14/F14 -> 16375 | H14: =ROUND(G14/500,0)*500 -> 16500 | I14: =H14-E14 -> 3400 | J14: =I14/H14 -> 0.20606061
B16: RATA-RATA | C16: =AVERAGE(C5:C14) -> 8545 | D16: =AVERAGE(D5:D14) -> 4000 | E16: =AVERAGE(E5:E14) -> 12545 | F16: =AVERAGE(F5:F14) -> 0.8 | G16: =AVERAGE(G5:G14) -> 15681.25 | H16: =AVERAGE(H5:H14) -> 15650 | I16: =AVERAGE(I5:I14) -> 3105 | J16: =AVERAGE(J5:J14) -> 0.19791335
A19: - Biaya Operasional per Cup (listrik, gas, air, penyusutan alat) adalah alokasi rata-rata Rp4.000 — sesuaikan dengan struktur biaya toko Anda.
A20: - PERHATIAN: Target Food Cost saat ini 80% (F kolom) -> margin hanya ~20%. Standar sehat industri F&B adalah food cost 30-40% (margin 60-70%). Pertimbangkan menaikkan harga jual atau menurunkan HPP agar margin lebih sehat.

Sheet Benchmark Kompetitor
A1: SINGGAH COFFEE — BENCHMARK KOMPETITOR
A2: Riset menu & harga Kopi Kenangan dan Point Coffee (sumber: web publik, per Jul 2026) sebagai acuan positioning harga Singgah Coffee.
A4: A. KOPI KENANGAN — MENU SIGNATURE & HARGA
A5: No | B5: Nama Menu | C5: Deskripsi Singkat | D5: Kisaran Harga (Rp) | E5: Catatan
A6: 1 | B6: Kopi Kenangan Mantan | C6: Espresso + susu segar + gula aren asli, signature/best seller sejak awal berdiri | D6: 18.000 - 25.000 | E6: Menu paling ikonik & paling sering direkomendasikan ke pelanggan baru
A7: 2 | B7: Kopi Kenangan Mantan Less Sugar | C7: Versi gula lebih sedikit dari Mantan, makin populer karena tren less-sugar | D7: 18.000 - 25.000 | E7: Naik daun seiring kesadaran konsumsi gula
A8: 3 | B8: Cloud Caramel Macchiato | C8: Espresso + susu + saus salted caramel, versi 'cloud' pakai cloud foam lembut | D8: 25.000 - 34.000 | E8: Tersedia panas & dingin
A9: 4 | B9: Creamy Aren Latte | C9: Latte gula aren dengan tekstur lebih creamy | D9: 22.000 - 28.000 | E9: Salah satu menu populer tetap
A10: 5 | B10: Kopi Oreo Latte | C10: Kopi susu + remahan biskuit Oreo | D10: 30.000 - 34.000 | E10: Segmen non-purist coffee drinker
A11: 6 | B11: Oatside Series (oat milk) | C11: Varian susu oat non-dairy untuk kopi & matcha | D11: 25.000 - 32.000 | E11: Menyasar pasar plant-based/intoleransi laktosa
A12: 7 | B12: Thai Green Tea | C12: Minuman non-kopi berbasis teh Thailand | D12: 18.000 - 22.000 | E12: Opsi untuk pelanggan non-kopi
A13: 8 | B13: Signature Bake (pastry) | C13: Kolaborasi dengan Chef Martin Praja - pastry & roti premium | D13: 15.000 - 25.000 | E13: Pendamping/pairing minuman
A15: B. POINT COFFEE — MENU SIGNATURE & HARGA
A16: No | B16: Nama Menu | C16: Deskripsi Singkat | D16: Kisaran Harga (Rp) | E16: Catatan
A17: 1 | B17: Iced Palm Sugar Latte | C17: Espresso + susu + gula aren, menu paling populer & sering dipromokan | D17: 20.000 - 25.000 | E17: Sering jadi bahan promo (mis. Rp1 via voucher)
A18: 2 | B18: Himalayan Butterscotch | C18: Espresso + susu + sirup butterscotch, rasa manis-gurih khas | D18: 20.000 - 25.000 | E18: Salah satu racikan andalan/unik
A19: 3 | B19: Caramel Macchiato | C19: Espresso + susu steamed + saus karamel | D19: 20.000 - 25.000 | E19: Tersedia panas/dingin
A20: 4 | B20: Iced Shaken Creamy Latte | C20: Kopi susu dikocok (shaken) dengan bahan signature, creamy & legit | D20: 20.000 - 25.000 | E20: Cocok untuk yang tidak suka kopi pahit
A21: 5 | B21: Hot Cappuccino | C21: Double shot espresso + susu steam berlapis foam tanpa gula | D21: 12.000 - 25.000 | E21: Disukai juga oleh non-penikmat kopi
A22: 6 | B22: Almond Latte | C22: Latte dengan sirup almond, aroma khas & gurih manis | D22: 20.000 - 25.000 | E22: Harga di kisaran Rp25.000
A23: 7 | B23: Signature Chocolate / Matcha | C23: Minuman non-kopi andalan, tersedia panas/dingin | D23: 20.000 - 25.000 | E23: Menyasar pelanggan non-kopi
A24: 8 | B24: Frappe Series | C24: Minuman blended kekinian, harga tertinggi di line up | D24: 25.000 - 30.000 | E24: Segmen premium/dessert drink
A26: C. INSIGHT UNTUK POSITIONING SINGGAH COFFEE
A27: - Rentang harga kedua brand nasional ini ada di Rp18.000-30.000/cup untuk menu reguler — Singgah Coffee di kisaran Rp9.000-22.000 (lihat sheet 'HPP & Harga Jual') masih di bawah rentang kompetitor, ada ruang untuk menaikkan harga.
A28: - Kopi susu gula aren (palm sugar latte) adalah pola resep yang konsisten dipakai kedua brand sebagai signature — sudah diakomodasi lewat menu 'Es Kopi Susu Gula Aren' dan versi premium 'Singgah Latte Gula Aren Susu Segar'.
A29: - 3 menu baru (Kopsu Singgah Aren, Butterscotch Latte, Kopsu Singgah) ditambahkan ke sheet 'Resep Menu' & 'HPP & Harga Jual' — resep dibuat versi 'terinspirasi', bukan reproduksi resep berhak cipta milik brand tersebut.
A30: - Kedua brand rutin bundling promo (mis. beli 2-3 cup harga spesial) — pertimbangkan strategi serupa untuk Singgah Coffee guna mendorong volume penjualan menuju BEP.

Sheet BEP
A1: SINGGAH COFFEE — BREAK EVEN POINT (BEP)
A2: Asumsi biaya tetap & operasional bulanan. Semua sel biru boleh disesuaikan dengan kondisi usaha Anda.
A4: A. BIAYA TETAP BULANAN (FIXED COST)
A5: No | B5: Komponen Biaya | C5: Nominal per Bulan (Rp) | D5: Keterangan
A6: 1 | B6: Retribusi/Parkir Lokasi Jualan | C6: 600000 | D6: Estimasi Rp20.000/hari x 30 hari — sesuaikan dgn lokasi mangkal Anda
A7: 2 | B7: Gaji/Upah Pemilik-Operator (diri sendiri) | C7: 1500000 | D7: Upah kerja sendiri sebagai barista solo — WAJIB dihitung agar tidak "gratis kerja"
A8: 3 | B8: BBM (Bensin) Mobil Kijang | C8: 500000 | D8: Estimasi mobilitas harian ke lokasi jualan
A9: 4 | B9: Gas LPG + Listrik/Charge Alat | C9: 200000 | D9: Kompor/pemanas air, charge alat elektronik
A10: 5 | B10: Penyusutan Peralatan & Kendaraan | C10: 300000 | D10: Mesin espresso portable, grinder, modifikasi mobil (disusutkan bulanan)
A11: 6 | B11: Perawatan & Servis Kendaraan | C11: 500000 | D11: Servis rutin, ganti oli, dll
A12: 7 | B12: Lain-lain / Tak Terduga (marketing, internet, dll) | C12: 300000 | D12: Media sosial, POS, kuota internet, dan tak terduga
B13: TOTAL BIAYA TETAP / BULAN | C13: =SUM(C6:C12) -> 3900000
A15: B. RATA-RATA HARGA JUAL & BIAYA VARIABEL (dari sheet HPP & Harga Jual)
B16: Rata-rata Harga Jual per Cup | C16: ='HPP & Harga Jual'!H16 -> 15650
B17: Rata-rata Biaya Variabel (HPP) per Cup | C17: ='HPP & Harga Jual'!E16 -> 12545
B18: Margin Kontribusi per Cup | C18: =C16-C17 -> 3105
A20: C. PERHITUNGAN BREAK EVEN POINT (BEP)
B21: BEP (Cup) per Bulan = Biaya Tetap / Margin Kontribusi per Cup | C21: =ROUNDUP(C13/C18,0) -> 1257
B22: BEP (Rupiah) per Bulan = Biaya Tetap / (1 - Biaya Variabel/Harga Jual) | C22: =C13/(1-(C17/C16)) -> 19657005
B23: BEP (Cup) per Hari (asumsi 30 hari operasional/bulan) | C23: =ROUNDUP(C21/30,0) -> 42
A25: D. PROYEKSI PENJUALAN & LABA
B26: Estimasi Penjualan per Hari (cup) | C26: ='Kebutuhan Stok'!G21 -> 50 | D26: Otomatis dari 'Kebutuhan Stok' (Total Target Cup / Periode Hari)
B27: Estimasi Penjualan per Bulan (30 hari) | C27: =C26*30 -> 1500
B28: Proyeksi Laba Bersih per Bulan = (Cup Terjual x Margin Kontribusi) - Biaya Tetap | C28: =(C27*C18)-C13 -> 757500
B29: Status terhadap BEP | C29: =IF(C27>=C21,"✓ SUDAH MELEWATI BEP","BELUM MENCAPAI BEP") -> ✓ SUDAH MELEWATI BEP
A31: E. ESTIMASI BALIK MODAL (PAYBACK PERIOD)
B32: Modal Awal Usaha (peralatan, renovasi, interior, dll) | C32: 40000000
B33: Estimasi Balik Modal (bulan) = Modal Awal / Proyeksi Laba Bersih per Bulan | C33: =IF(C28>0,ROUNDUP(C32/C28,1),"Laba belum positif") -> 52.9
A35: Catatan:
A36: - Seluruh nominal biaya tetap, estimasi penjualan, dan modal awal adalah ASUMSI riset pasar (skala kedai kecil-menengah) — wajib disesuaikan dengan kondisi riil Singgah Coffee.
A37: - Rumus BEP mengikuti metode standar (Mekari Jurnal, KoinWorks): BEP unit = Biaya Tetap / Margin Kontribusi; BEP rupiah = Biaya Tetap / (1 - Biaya Variabel/Harga Jual).
